try{
	const a = 1;
	const b = a+c;
	console.log("No Exception");
}catch(err) {
	console.log(err);
}